<?xml version="1.0" ?>
<!-- =================================================================================== -->
<!-- |    This document was autogenerated by xacro from segway.urdf.xacro              | -->
<!-- |    EDITING THIS FILE BY HAND IS NOT RECOMMENDED                                 | -->
<!-- =================================================================================== -->
<robot name="segway">
  <link name="base_frame">
    <visual>
      <origin rpy="0 0 0" xyz="0 0 0.375"/>
      <geometry>
        <box size="0.5 0.5 0.75"/>
      </geometry>
    </visual>
    <collision>
      <origin rpy="0 0 0" xyz="0 0 0.375"/>
      <geometry>
        <box size="0.5 0.5 0.75"/>
      </geometry>
    </collision>
  </link>
  <!-- wheels for tracks -->
  <link name="left_wheel">
    <visual>
      <origin rpy="1.5707963267948966 0 0" xyz="0.0 0.0 0.0"/>
      <geometry>
        <cylinder length="0.05" radius="0.2"/>
      </geometry>
      <material name="wheel_black">
        <color rgba="0 0 0 1"/>
      </material>
    </visual>
    <collision>
      <origin rpy="1.5707963267948966 0 0" xyz="0.0 0.0 0.0"/>
      <geometry>
        <cylinder length="0.05" radius="0.2"/>
      </geometry>
    </collision>
  </link>
  <joint name="left_wheel_joint" type="continuous">
    <origin rpy="0 0 0" xyz="0 -0.3 0"/>
    <axis xyz="0 1 0"/>
    <parent link="base_frame"/>
    <child link="left_wheel"/>
  </joint>
  <!-- wheels for tracks -->
  <link name="right_wheel">
    <visual>
      <origin rpy="1.5707963267948966 0 0" xyz="0.0 0.0 0.0"/>
      <geometry>
        <cylinder length="0.05" radius="0.2"/>
      </geometry>
      <material name="wheel_black">
        <color rgba="0 0 0 1"/>
      </material>
    </visual>
    <collision>
      <origin rpy="1.5707963267948966 0 0" xyz="0.0 0.0 0.0"/>
      <geometry>
        <cylinder length="0.05" radius="0.2"/>
      </geometry>
    </collision>
  </link>
  <joint name="right_wheel_joint" type="continuous">
    <origin rpy="0 0 0" xyz="0 0.3 0"/>
    <axis xyz="0 1 0"/>
    <parent link="base_frame"/>
    <child link="right_wheel"/>
  </joint>
  <ros2_control name="SegwayHardwareInterface" type="system">
    <hardware>
      <plugin>agx_sim_ros2/AGXHardwareInterface</plugin>
    </hardware>
    <joint name="left_wheel_joint">
      <param name="agx_name">left_wheel_joint</param>
      <param name="sign">1</param>
      <command_interface name="velocity">
        <param name="min">-1.0</param>
        <param name="max">1.0</param>
      </command_interface>
      <state_interface name="position"/>
      <state_interface name="velocity"/>
      <state_interface name="effort"/>
    </joint>
    <joint name="right_wheel_joint">
      <param name="agx_name">right_wheel_joint</param>
      <param name="sign">1</param>
      <command_interface name="velocity">
        <param name="min">-1.0</param>
        <param name="max">1.0</param>
      </command_interface>
      <state_interface name="position"/>
      <state_interface name="velocity"/>
      <state_interface name="effort"/>
    </joint>
  </ros2_control>
</robot>
